<?xml version="1.0" ?>
<!-- =================================================================================== -->
<!-- |    This document was autogenerated by xacro from bot_description.urdf.xacro     | -->
<!-- |    EDITING THIS FILE BY HAND IS NOT RECOMMENDED                                 | -->
<!-- =================================================================================== -->
<robot name="my_bot">
  <material name="green">
    <color rgba="0 0.5 0 1"/>
  </material>
  <material name="pink">
    <color rgba="1 0.5 0.5 1"/>
  </material>
  <material name="blue">
    <color rgba="0 0 0.5 1"/>
  </material>
  <link name="lidar_link">
    <visual>
      <geometry>
        <cylinder length="0.02" radius="0.03"/>
      </geometry>
      <origin rpy="0 0 0" xyz="0 0 0.01"/>
      <material name="blue"/>
    </visual>
    <collision>
      <geometry>
        <cylinder length="0.02" radius="0.03"/>
      </geometry>
      <origin rpy="0 0 0" xyz="0 0 0.01"/>
    </collision>
    <inertial>
      <origin rpy="0 0 0" xyz="0 0 0.01"/>
      <mass value="0.3"/>
      <inertia ixx="7.749999999999999e-05" ixy="0" ixz="0" iyy="7.749999999999999e-05" iyz="0" izz="0.000135"/>
    </inertial>
  </link>
  <link name="camera_link">
    <visual>
      <geometry>
        <box size="0.01 0.03 0.03"/>
      </geometry>
      <origin rpy="0 0 0" xyz="0 0 0"/>
      <material name="pink"/>
    </visual>
    <collision>
      <geometry>
        <box size="0.01 0.03 0.03"/>
      </geometry>
      <origin rpy="0 0 0" xyz="0 0 0"/>
    </collision>
    <inertial>
      <origin rpy="0 0 0" xyz="0 0 0"/>
      <mass value="0.1"/>
      <inertia ixx="8.333333333333334e-06" ixy="0" ixz="0" iyy="8.333333333333334e-06" iyz="0" izz="1.4999999999999999e-05"/>
    </inertial>
  </link>
  <joint name="base_lidar_joint" type="fixed">
    <parent link="base_link"/>
    <child link="lidar_link"/>
    <origin rpy="0 0 0" xyz="0.05 0 0.1"/>
  </joint>
  <joint name="base_link_camera_link_joint" type="fixed">
    <parent link="base_link"/>
    <child link="camera_link"/>
    <origin rpy="0 0 0" xyz="0.10500000000000001 0 0.07142857142857144"/>
  </joint>
  <link name="base_footprint"/>
  <link name="base_link">
    <visual>
      <geometry>
        <box size="0.2 0.2 0.1"/>
      </geometry>
      <origin rpy="0 0 0" xyz="0 0 0.05"/>
      <material name="green"/>
    </visual>
    <collision>
      <geometry>
        <box size="0.2 0.2 0.1"/>
      </geometry>
      <origin rpy="0 0 0" xyz="0 0 0.05"/>
    </collision>
    <inertial>
      <origin rpy="0 0 0" xyz="0 0 0.05"/>
      <mass value="2.0"/>
      <inertia ixx="0.008333333333333335" ixy="0" ixz="0" iyy="0.013333333333333336" iyz="0" izz="0.008333333333333335"/>
    </inertial>
  </link>
  <link name="right_wheel_link">
    <visual>
      <geometry>
        <cylinder length="0.02" radius="0.06"/>
      </geometry>
      <origin rpy="1.5707963267948966 0 0" xyz="0 0 0"/>
      <material name="pink"/>
    </visual>
    <collision>
      <geometry>
        <cylinder length="0.02" radius="0.06"/>
      </geometry>
      <origin rpy="1.5707963267948966 0 0" xyz="0 0 0"/>
    </collision>
    <inertial>
      <origin rpy="1.5707963267948966 0 0" xyz="0 0 0"/>
      <mass value="0.3"/>
      <inertia ixx="0.0002799999999999999" ixy="0" ixz="0" iyy="0.0002799999999999999" iyz="0" izz="0.00054"/>
    </inertial>
  </link>
  <link name="left_wheel_link">
    <visual>
      <geometry>
        <cylinder length="0.02" radius="0.06"/>
      </geometry>
      <origin rpy="1.5707963267948966 0 0" xyz="0 0 0"/>
      <material name="pink"/>
    </visual>
    <collision>
      <geometry>
        <cylinder length="0.02" radius="0.06"/>
      </geometry>
      <origin rpy="1.5707963267948966 0 0" xyz="0 0 0"/>
    </collision>
    <inertial>
      <origin rpy="1.5707963267948966 0 0" xyz="0 0 0"/>
      <mass value="0.3"/>
      <inertia ixx="0.0002799999999999999" ixy="0" ixz="0" iyy="0.0002799999999999999" iyz="0" izz="0.00054"/>
    </inertial>
  </link>
  <link name="front_wheel_link">
    <visual>
      <geometry>
        <sphere radius="0.02"/>
      </geometry>
      <origin rpy="0 0 0" xyz="0 0 0"/>
      <material name="pink"/>
    </visual>
    <collision>
      <geometry>
        <sphere radius="0.02"/>
      </geometry>
      <origin rpy="0 0 0" xyz="0 0 0"/>
    </collision>
    <inertial>
      <origin rpy="0 0 0" xyz="0 0 0"/>
      <mass value="0.1"/>
      <inertia ixx="1.6000000000000003e-05" ixy="0" ixz="0" iyy="1.6000000000000003e-05" iyz="0" izz="1.6000000000000003e-05"/>
    </inertial>
  </link>
  <joint name="base_footprint_base_link_joint" type="fixed">
    <parent link="base_footprint"/>
    <child link="base_link"/>
    <origin rpy="0 0 0" xyz="0 0 0.02"/>
  </joint>
  <joint name="base_left_wheel_joint" type="continuous">
    <parent link="base_link"/>
    <child link="left_wheel_link"/>
    <origin rpy="0 0 0" xyz="-0.035 0.11 0.040"/>
    <axis xyz="0 1 0"/>
  </joint>
  <joint name="base_right_wheel_joint" type="continuous">
    <parent link="base_link"/>
    <child link="right_wheel_link"/>
    <origin rpy="0 0 0" xyz="-0.035 -0.11 0.040"/>
    <axis xyz="0 1 0"/>
  </joint>
  <joint name="base_front_wheel_joint" type="fixed">
    <parent link="base_link"/>
    <child link="front_wheel_link"/>
    <origin rpy="0 0 0" xyz="0.061 0 0"/>
  </joint>
</robot>
